Workbook

Sheet LeaderBoard WoW
A2: Employee Name | B2: Total GCP Points W13-01 | C2: Total GCP Points W20-01 | D2: Change WoW
A3: Amandeep Singh | B3: 357 | C3: 372 | D3: =IF(C3>B3,C3-B3,IF(C3<B3,C3-B3,0)) -> 15
A4: Andres Felipe Lagos Ruiz | B4: 354 | C4: 354 | D4: =IF(C4>B4,C4-B4,IF(C4<B4,C4-B4,0)) -> 0
A5: Venkatesh Coimbatore Kannan | B5: 264 | C5: 264 | D5: =IF(C5>B5,C5-B5,IF(C5<B5,C5-B5,0)) -> 0
A6: Ankit Pandey | B6: 217 | C6: 217 | D6: =IF(C6>B6,C6-B6,IF(C6<B6,C6-B6,0)) -> 0
A7: Richard Saavedra | B7: 183 | C7: 183 | D7: =IF(C7>B7,C7-B7,IF(C7<B7,C7-B7,0)) -> 0
A8: Abhinav Chandna | B8: 125 | C8: 125 | D8: =IF(C8>B8,C8-B8,IF(C8<B8,C8-B8,0)) -> 0
A9: Raman Bangalore Venkatakrishnan | B9: 123 | C9: 123 | D9: =IF(C9>B9,C9-B9,IF(C9<B9,C9-B9,0)) -> 0
A10: Ka Ho Ng | B10: 90 | C10: 90 | D10: =IF(C10>B10,C10-B10,IF(C10<B10,C10-B10,0)) -> 0
A11: Igor Wilk | B11: 75 | C11: 75 | D11: =IF(C11>B11,C11-B11,IF(C11<B11,C11-B11,0)) -> 0
A12: Luis Vilches | B12: 70 | C12: 70 | D12: =IF(C12>B12,C12-B12,IF(C12<B12,C12-B12,0)) -> 0
A13: Camila Da Silveira | B13: 70 | C13: 70 | D13: =IF(C13>B13,C13-B13,IF(C13<B13,C13-B13,0)) -> 0
A14: Fernando Espinoza | B14: 60 | C14: 60 | D14: =IF(C14>B14,C14-B14,IF(C14<B14,C14-B14,0)) -> 0
... A29: Bruno Rodríguez | B29: 5 | C29: 10 | D29: =IF(C29>B29,C29-B29,IF(C29<B29,C29-B29,0)) -> 5
A30: Grand Total | B30: =SUM(B3:B29) -> 2345 | C30: =SUM(C3:C29) -> 2375 | D30: =IF(C30>B30,C30-B30,IF(C30<B30,C30-B30,0)) -> 30

Sheet Leaderboards
A2: Employee Name | B2: Total GCP Points
A3: Amandeep Singh | B3: 372
A4: Andres Felipe Lagos Ruiz | B4: 354
A5: Venkatesh Coimbatore Kannan | B5: 264
A6: Ankit Pandey | B6: 217
A7: Richard Saavedra | B7: 183
A8: Abhinav Chandna | B8: 125
A9: Raman Bangalore Venkatakrishnan | B9: 123
A10: Ka Ho Ng | B10: 90
A11: Igor Wilk | B11: 75
A12: Luis Vilches | B12: 70
A13: Camila Da Silveira | B13: 70
A14: Fernando Espinoza | B14: 60
... A30: Grand Total | B30: 2375

Sheet DA Summary
A1: EMP ID | B1: Entity | C1: Employee Name | D1: Designation | E1: Level | F1: RM Name | G1: LOB | H1: Sub Lob | I1: Category | J1: ROLE | K1: Practice | L1: Practice Leader | M1: Certificate mapping | N1: BigQuery | O1: Looker | P1: Dataflow | Q1: Dataproc | R1: GKE | S1: Apigee | T1: Cloud Run | U1: Workspace | V1: Cloud SQL | W1: AlloyDB | X1: Spanner | Y1: Oracle | Z1: GCE | AA1: GCN | AB1: SAP | AC1: VMware | AD1: GDC | AE1: Cloud Sec. | AF1: SCC | AG1: SecOps | AH1: GTI | AI1: Vertex AI | AJ1: AI App | AK1: Gemini | AL1: CES | AM1: Grand Total
A2: CAN-20796 | B2: CAN | C2: Abhinandan Singh Jamwal | D2: Consultant | E2: L4 | F2: Nishant Saxena | G2: CIDA-05 | H2: CIDA-05-3 | I2: Ops | J2: BI Developer | K2: DM | L2: Nishant Saxena | N2: =VLOOKUP(C2,BigQuery!$1:$1048576,10,FALSE) -> 0 | O2: =VLOOKUP(C2,Looker!$1:$1048576,10,FALSE) -> 0 | P2: =VLOOKUP(C2,Dataflow!$1:$1048576,10,FALSE) -> 0 | Q2: =VLOOKUP(C2,Dataproc!$1:$1048576,10,FALSE) -> 0 | R2: =VLOOKUP(C2,'Google Kubernetes Engine'!$1:$1048576,10,FALSE) -> 0 | S2: =VLOOKUP(C2,'Apigee API Management'!$1:$1048576,10,FALSE) -> 0 | T2: =VLOOKUP(C2,'Cloud Run'!$1:$1048576,10,FALSE) -> 0 | U2: =VLOOKUP(C2,Workspace!$1:$1048576,10,FALSE) -> 0 | V2: =VLOOKUP(C2,'Cloud SQL'!$1:$1048576,10,FALSE) -> 0 | W2: =VLOOKUP(C2,'AlloyDB for PostgreSQL'!$1:$1048576,10,FALSE) -> 0 | X2: =VLOOKUP(C2,Spanner!$1:$1048576,10,FALSE) -> 0 | Y2: =VLOOKUP(C2,Oracle!$1:$1048576,10,FALSE) -> 0 | Z2: =VLOOKUP(C2,'Google Compute Engine'!$1:$1048576,10,FALSE) -> 0 | AA2: =VLOOKUP(C2,'Google Cloud Networking'!$1:$1048576,10,FALSE) -> 0 | AB2: =VLOOKUP(C2,'SAP on Google Cloud'!$1:$1048576,10,FALSE) -> 0 | AC2: =VLOOKUP(C2,'Google Cloud VMware Engine'!$1:$1048576,10,FALSE) -> 0 | AD2: =VLOOKUP(C2,'Google Distributed Cloud'!$1:$1048576,10,FALSE) -> 0 | AE2: =VLOOKUP(C2,'Cloud Security'!$1:$1048576,10,FALSE) -> 0 | AF2: =VLOOKUP(C2,'Security Command Center'!$1:$1048576,10,FALSE) -> 0 | AG2: =VLOOKUP(C2,'Security Operations'!$1:$1048576,10,FALSE) -> 0 | AH2: =VLOOKUP(C2,'Google Threat Intelligence'!$1:$1048576,10,FALSE) -> 0 | AI2: =VLOOKUP(C2,'Vertex AI Platform'!$1:$1048576,10,FALSE) -> 0 | AJ2: =VLOOKUP(C2,'AI Applications'!$1:$1048576,10,FALSE) -> 0 | AK2: =VLOOKUP(C2,'Gemini Enterprise'!$1:$1048576,10,FALSE) -> 0 | AL2: =VLOOKUP(C2,'Customer Engagement Suite'!$1:$1048576,10,FALSE) -> 0 | AM2: =SUM(N2:AL2) -> 0
A3: CAN-23494 | B3: CAN | C3: Abhinav Chandna | D3: Senior Consultant | E3: L5 | F3: Venkatesh Kannan | G3: CIDA-05 | H3: CIDA-05-1 | I3: Ops | J3: Data Engineer | K3: DE | L3: Venkatesh Coimbatore Kannan | N3: =VLOOKUP(C3,BigQuery!$1:$1048576,10,FALSE) -> 34 | O3: =VLOOKUP(C3,Looker!$1:$1048576,10,FALSE) -> 14 | P3: =VLOOKUP(C3,Dataflow!$1:$1048576,10,FALSE) -> 39 | Q3: =VLOOKUP(C3,Dataproc!$1:$1048576,10,FALSE) -> 24 | R3: =VLOOKUP(C3,'Google Kubernetes Engine'!$1:$1048576,10,FALSE) -> 0 | S3: =VLOOKUP(C3,'Apigee API Management'!$1:$1048576,10,FALSE) -> 0 | T3: =VLOOKUP(C3,'Cloud Run'!$1:$1048576,10,FALSE) -> 0 | U3: =VLOOKUP(C3,Workspace!$1:$1048576,10,FALSE) -> 0 | V3: =VLOOKUP(C3,'Cloud SQL'!$1:$1048576,10,FALSE) -> 0 | W3: =VLOOKUP(C3,'AlloyDB for PostgreSQL'!$1:$1048576,10,FALSE) -> 0 | X3: =VLOOKUP(C3,Spanner!$1:$1048576,10,FALSE) -> 0 | Y3: =VLOOKUP(C3,Oracle!$1:$1048576,10,FALSE) -> 0 | Z3: =VLOOKUP(C3,'Google Compute Engine'!$1:$1048576,10,FALSE) -> 0 | AA3: =VLOOKUP(C3,'Google Cloud Networking'!$1:$1048576,10,FALSE) -> 0 | AB3: =VLOOKUP(C3,'SAP on Google Cloud'!$1:$1048576,10,FALSE) -> 0 | AC3: =VLOOKUP(C3,'Google Cloud VMware Engine'!$1:$1048576,10,FALSE) -> 0 | AD3: =VLOOKUP(C3,'Google Distributed Cloud'!$1:$1048576,10,FALSE) -> 0 | AE3: =VLOOKUP(C3,'Cloud Security'!$1:$1048576,10,FALSE) -> 0 | AF3: =VLOOKUP(C3,'Security Command Center'!$1:$1048576,10,FALSE) -> 0 | AG3: =VLOOKUP(C3,'Security Operations'!$1:$1048576,10,FALSE) -> 0 | AH3: =VLOOKUP(C3,'Google Threat Intelligence'!$1:$1048576,10,FALSE) -> 0 | AI3: =VLOOKUP(C3,'Vertex AI Platform'!$1:$1048576,10,FALSE) -> 14 | AJ3: =VLOOKUP(C3,'AI Applications'!$1:$1048576,10,FALSE) -> 0 | AK3: =VLOOKUP(C3,'Gemini Enterprise'!$1:$1048576,10,FALSE) -> 0 | AL3: =VLOOKUP(C3,'Customer Engagement Suite'!$1:$1048576,10,FALSE) -> 0 | AM3: =SUM(N3:AL3) -> 125
A4: INC-24352 | B4: INC | C4: Kumar Shiveshwar | D4: Junior Analyst | E4: L1 | F4: Duwage Gunasekara | G4: CIDA-05 | H4: CIDA-05-2 | I4: Ops | J4: Data Scientist | K4: DS | L4: Rajat Singh | N4: =VLOOKUP(C4,BigQuery!$1:$1048576,10,FALSE) -> 0 | O4: =VLOOKUP(C4,Looker!$1:$1048576,10,FALSE) -> 0 | P4: =VLOOKUP(C4,Dataflow!$1:$1048576,10,FALSE) -> 0 | Q4: =VLOOKUP(C4,Dataproc!$1:$1048576,10,FALSE) -> 0 | R4: =VLOOKUP(C4,'Google Kubernetes Engine'!$1:$1048576,10,FALSE) -> 0 | S4: =VLOOKUP(C4,'Apigee API Management'!$1:$1048576,10,FALSE) -> 0 | T4: =VLOOKUP(C4,'Cloud Run'!$1:$1048576,10,FALSE) -> 0 | U4: =VLOOKUP(C4,Workspace!$1:$1048576,10,FALSE) -> 0 | V4: =VLOOKUP(C4,'Cloud SQL'!$1:$1048576,10,FALSE) -> 0 | W4: =VLOOKUP(C4,'AlloyDB for PostgreSQL'!$1:$1048576,10,FALSE) -> 0 | X4: =VLOOKUP(C4,Spanner!$1:$1048576,10,FALSE) -> 0 | Y4: =VLOOKUP(C4,Oracle!$1:$1048576,10,FALSE) -> 0 | Z4: =VLOOKUP(C4,'Google Compute Engine'!$1:$1048576,10,FALSE) -> 0 | AA4: =VLOOKUP(C4,'Google Cloud Networking'!$1:$1048576,10,FALSE) -> 0 | AB4: =VLOOKUP(C4,'SAP on Google Cloud'!$1:$1048576,10,FALSE) -> 0 | AC4: =VLOOKUP(C4,'Google Cloud VMware Engine'!$1:$1048576,10,FALSE) -> 0 | AD4: =VLOOKUP(C4,'Google Distributed Cloud'!$1:$1048576,10,FALSE) -> 0 | AE4: =VLOOKUP(C4,'Cloud Security'!$1:$1048576,10,FALSE) -> 0 | AF4: =VLOOKUP(C4,'Security Command Center'!$1:$1048576,10,FALSE) -> 0 | AG4: =VLOOKUP(C4,'Security Operations'!$1:$1048576,10,FALSE) -> 0 | AH4: =VLOOKUP(C4,'Google Threat Intelligence'!$1:$1048576,10,FALSE) -> 0 | AI4: =VLOOKUP(C4,'Vertex AI Platform'!$1:$1048576,10,FALSE) -> 0 | AJ4: =VLOOKUP(C4,'AI Applications'!$1:$1048576,10,FALSE) -> 0 | AK4: =VLOOKUP(C4,'Gemini Enterprise'!$1:$1048576,10,FALSE) -> 0 | AL4: =VLOOKUP(C4,'Customer Engagement Suite'!$1:$1048576,10,FALSE) -> 0 | AM4: =SUM(N4:AL4) -> 0
A5: CHI-9082 | B5: CHI | C5: Alvaro Flores | D5: Senior Consultant | E5: L5 | F5: Daniel Gatica | G5: CIDA-01 | H5: CIDA-01-1 | I5: Ops | J5: Data Engineer | K5: DE | L5: Venkatesh Coimbatore Kannan | N5: =VLOOKUP(C5,BigQuery!$1:$1048576,10,FALSE) -> 0 | O5: =VLOOKUP(C5,Looker!$1:$1048576,10,FALSE) -> 0 | P5: =VLOOKUP(C5,Dataflow!$1:$1048576,10,FALSE) -> 0 | Q5: =VLOOKUP(C5,Dataproc!$1:$1048576,10,FALSE) -> 0 | R5: =VLOOKUP(C5,'Google Kubernetes Engine'!$1:$1048576,10,FALSE) -> 0 | S5: =VLOOKUP(C5,'Apigee API Management'!$1:$1048576,10,FALSE) -> 0 | T5: =VLOOKUP(C5,'Cloud Run'!$1:$1048576,10,FALSE) -> 0 | U5: =VLOOKUP(C5,Workspace!$1:$1048576,10,FALSE) -> 0 | V5: =VLOOKUP(C5,'Cloud SQL'!$1:$1048576,10,FALSE) -> 0 | W5: =VLOOKUP(C5,'AlloyDB for PostgreSQL'!$1:$1048576,10,FALSE) -> 0 | X5: =VLOOKUP(C5,Spanner!$1:$1048576,10,FALSE) -> 0 | Y5: =VLOOKUP(C5,Oracle!$1:$1048576,10,FALSE) -> 0 | Z5: =VLOOKUP(C5,'Google Compute Engine'!$1:$1048576,10,FALSE) -> 0 | AA5: =VLOOKUP(C5,'Google Cloud Networking'!$1:$1048576,10,FALSE) -> 0 | AB5: =VLOOKUP(C5,'SAP on Google Cloud'!$1:$1048576,10,FALSE) -> 0 | AC5: =VLOOKUP(C5,'Google Cloud VMware Engine'!$1:$1048576,10,FALSE) -> 0 | AD5: =VLOOKUP(C5,'Google Distributed Cloud'!$1:$1048576,10,FALSE) -> 0 | AE5: =VLOOKUP(C5,'Cloud Security'!$1:$1048576,10,FALSE) -> 0 | AF5: =VLOOKUP(C5,'Security Command Center'!$1:$1048576,10,FALSE) -> 0 | AG5: =VLOOKUP(C5,'Security Operations'!$1:$1048576,10,FALSE) -> 0 | AH5: =VLOOKUP(C5,'Google Threat Intelligence'!$1:$1048576,10,FALSE) -> 0 | AI5: =VLOOKUP(C5,'Vertex AI Platform'!$1:$1048576,10,FALSE) -> 0 | AJ5: =VLOOKUP(C5,'AI Applications'!$1:$1048576,10,FALSE) -> 0 | AK5: =VLOOKUP(C5,'Gemini Enterprise'!$1:$1048576,10,FALSE) -> 0 | AL5: =VLOOKUP(C5,'Customer Engagement Suite'!$1:$1048576,10,FALSE) -> 0 | AM5: =SUM(N5:AL5) -> 0
A6: CHI-14611 | B6: CHI | C6: Amandeep Singh | D6: Principal Consultant | E6: L6 | F6: Walter Paredes | G6: CIDA-01 | H6: CIDA-01-6 | I6: Ops | J6: ML Engineer | K6: SD | L6: Walter Paredes | M6: Professional Cloud DevOps Engineer | N6: =VLOOKUP(C6,BigQuery!$1:$1048576,10,FALSE) -> 24 | O6: =VLOOKUP(C6,Looker!$1:$1048576,10,FALSE) -> 0 | P6: =VLOOKUP(C6,Dataflow!$1:$1048576,10,FALSE) -> 19 | Q6: =VLOOKUP(C6,Dataproc!$1:$1048576,10,FALSE) -> 0 | R6: =VLOOKUP(C6,'Google Kubernetes Engine'!$1:$1048576,10,FALSE) -> 39 | S6: =VLOOKUP(C6,'Apigee API Management'!$1:$1048576,10,FALSE) -> 19 | T6: =VLOOKUP(C6,'Cloud Run'!$1:$1048576,10,FALSE) -> 44 | U6: =VLOOKUP(C6,Workspace!$1:$1048576,10,FALSE) -> 0 | V6: =VLOOKUP(C6,'Cloud SQL'!$1:$1048576,10,FALSE) -> 14 | W6: =VLOOKUP(C6,'AlloyDB for PostgreSQL'!$1:$1048576,10,FALSE) -> 0 | X6: =VLOOKUP(C6,Spanner!$1:$1048576,10,FALSE) -> 0 | Y6: =VLOOKUP(C6,Oracle!$1:$1048576,10,FALSE) -> 0 | Z6: =VLOOKUP(C6,'Google Compute Engine'!$1:$1048576,10,FALSE) -> 24 | AA6: =VLOOKUP(C6,'Google Cloud Networking'!$1:$1048576,10,FALSE) -> 34 | AB6: =VLOOKUP(C6,'SAP on Google Cloud'!$1:$1048576,10,FALSE) -> 0 | AC6: =VLOOKUP(C6,'Google Cloud VMware Engine'!$1:$1048576,10,FALSE) -> 0 | AD6: =VLOOKUP(C6,'Google Distributed Cloud'!$1:$1048576,10,FALSE) -> 0 | AE6: =VLOOKUP(C6,'Cloud Security'!$1:$1048576,10,FALSE) -> 19 | AF6: =VLOOKUP(C6,'Security Command Center'!$1:$1048576,10,FALSE) -> 0 | AG6: =VLOOKUP(C6,'Security Operations'!$1:$1048576,10,FALSE) -> 0 | AH6: =VLOOKUP(C6,'Google Threat Intelligence'!$1:$1048576,10,FALSE) -> 0 | AI6: =VLOOKUP(C6,'Vertex AI Platform'!$1:$1048576,10,FALSE) -> 49 | AJ6: =VLOOKUP(C6,'AI Applications'!$1:$1048576,10,FALSE) -> 44 | AK6: =VLOOKUP(C6,'Gemini Enterprise'!$1:$1048576,10,FALSE) -> 24 | AL6: =VLOOKUP(C6,'Customer Engagement Suite'!$1:$1048576,10,FALSE) -> 19 | AM6: =SUM(N6:AL6) -> 372
A7: COL-21961 | B7: COL | C7: Andres Felipe Lagos Ruiz | D7: Senior Analyst | E7: L3 | F7: Lawrence Setien | G7: CIDA-01 | H7: CIDA-01-1 | I7: Ops | J7: Data Engineer | K7: DE | L7: Venkatesh Coimbatore Kannan | N7: =VLOOKUP(C7,BigQuery!$1:$1048576,10,FALSE) -> 29 | O7: =VLOOKUP(C7,Looker!$1:$1048576,10,FALSE) -> 19 | P7: =VLOOKUP(C7,Dataflow!$1:$1048576,10,FALSE) -> 19 | Q7: =VLOOKUP(C7,Dataproc!$1:$1048576,10,FALSE) -> 19 | R7: =VLOOKUP(C7,'Google Kubernetes Engine'!$1:$1048576,10,FALSE) -> 19 | S7: =VLOOKUP(C7,'Apigee API Management'!$1:$1048576,10,FALSE) -> 0 | T7: =VLOOKUP(C7,'Cloud Run'!$1:$1048576,10,FALSE) -> 0 | U7: =VLOOKUP(C7,Workspace!$1:$1048576,10,FALSE) -> 0 | V7: =VLOOKUP(C7,'Cloud SQL'!$1:$1048576,10,FALSE) -> 19 | W7: =VLOOKUP(C7,'AlloyDB for PostgreSQL'!$1:$1048576,10,FALSE) -> 29 | X7: =VLOOKUP(C7,Spanner!$1:$1048576,10,FALSE) -> 24 | Y7: =VLOOKUP(C7,Oracle!$1:$1048576,10,FALSE) -> 19 | Z7: =VLOOKUP(C7,'Google Compute Engine'!$1:$1048576,10,FALSE) -> 34 | AA7: =VLOOKUP(C7,'Google Cloud Networking'!$1:$1048576,10,FALSE) -> 29 | AB7: =VLOOKUP(C7,'SAP on Google Cloud'!$1:$1048576,10,FALSE) -> 19 | AC7: =VLOOKUP(C7,'Google Cloud VMware Engine'!$1:$1048576,10,FALSE) -> 19 | AD7: =VLOOKUP(C7,'Google Distributed Cloud'!$1:$1048576,10,FALSE) -> 24 | AE7: =VLOOKUP(C7,'Cloud Security'!$1:$1048576,10,FALSE) -> 0 | AF7: =VLOOKUP(C7,'Security Command Center'!$1:$1048576,10,FALSE) -> 0 | AG7: =VLOOKUP(C7,'Security Operations'!$1:$1048576,10,FALSE) -> 0 | AH7: =VLOOKUP(C7,'Google Threat Intelligence'!$1:$1048576,10,FALSE) -> 0 | AI7: =VLOOKUP(C7,'Vertex AI Platform'!$1:$1048576,10,FALSE) -> 0 | AJ7: =VLOOKUP(C7,'AI Applications'!$1:$1048576,10,FALSE) -> 19 | AK7: =VLOOKUP(C7,'Gemini Enterprise'!$1:$1048576,10,FALSE) -> 14 | AL7: =VLOOKUP(C7,'Customer Engagement Suite'!$1:$1048576,10,FALSE) -> 0 | AM7: =SUM(N7:AL7) -> 354
A8: INC-16832 | B8: INC | C8: Ankit Pandey | D8: Associate Director | E8: L7 | F8: Rajat Singh | G8: CIDA-01 | H8: CIDA-01-2 | I8: Ops | J8: Data Scientist | K8: DS | L8: Arnav Sharma | N8: =VLOOKUP(C8,BigQuery!$1:$1048576,10,FALSE) -> 34 | O8: =VLOOKUP(C8,Looker!$1:$1048576,10,FALSE) -> 19 | P8: =VLOOKUP(C8,Dataflow!$1:$1048576,10,FALSE) -> 34 | Q8: =VLOOKUP(C8,Dataproc!$1:$1048576,10,FALSE) -> 24 | R8: =VLOOKUP(C8,'Google Kubernetes Engine'!$1:$1048576,10,FALSE) -> 0 | S8: =VLOOKUP(C8,'Apigee API Management'!$1:$1048576,10,FALSE) -> 0 | T8: =VLOOKUP(C8,'Cloud Run'!$1:$1048576,10,FALSE) -> 0 | U8: =VLOOKUP(C8,Workspace!$1:$1048576,10,FALSE) -> 0 | V8: =VLOOKUP(C8,'Cloud SQL'!$1:$1048576,10,FALSE) -> 0 | W8: =VLOOKUP(C8,'AlloyDB for PostgreSQL'!$1:$1048576,10,FALSE) -> 0 | X8: =VLOOKUP(C8,Spanner!$1:$1048576,10,FALSE) -> 0 | Y8: =VLOOKUP(C8,Oracle!$1:$1048576,10,FALSE) -> 0 | Z8: =VLOOKUP(C8,'Google Compute Engine'!$1:$1048576,10,FALSE) -> 0 | AA8: =VLOOKUP(C8,'Google Cloud Networking'!$1:$1048576,10,FALSE) -> 0 | AB8: =VLOOKUP(C8,'SAP on Google Cloud'!$1:$1048576,10,FALSE) -> 0 | AC8: =VLOOKUP(C8,'Google Cloud VMware Engine'!$1:$1048576,10,FALSE) -> 0 | AD8: =VLOOKUP(C8,'Google Distributed Cloud'!$1:$1048576,10,FALSE) -> 0 | AE8: =VLOOKUP(C8,'Cloud Security'!$1:$1048576,10,FALSE) -> 0 | AF8: =VLOOKUP(C8,'Security Command Center'!$1:$1048576,10,FALSE) -> 0 | AG8: =VLOOKUP(C8,'Security Operations'!$1:$1048576,10,FALSE) -> 0 | AH8: =VLOOKUP(C8,'Google Threat Intelligence'!$1:$1048576,10,FALSE) -> 0 | AI8: =VLOOKUP(C8,'Vertex AI Platform'!$1:$1048576,10,FALSE) -> 49 | AJ8: =VLOOKUP(C8,'AI Applications'!$1:$1048576,10,FALSE) -> 19 | AK8: =VLOOKUP(C8,'Gemini Enterprise'!$1:$1048576,10,FALSE) -> 19 | AL8: =VLOOKUP(C8,'Customer Engagement Suite'!$1:$1048576,10,FALSE) -> 19 | AM8: =SUM(N8:AL8) -> 217
A9: INC-17749 | B9: INC | C9: Apeksha Sharma | D9: Consultant | E9: L4 | F9: Raman Bangalore Venkatakr | G9: CIDA-05 | H9: CIDA-05-4 | I9: Ops | J9: Data Engineer | K9: BI | L9: Walter Paredes | N9: =VLOOKUP(C9,BigQuery!$1:$1048576,10,FALSE) -> 0 | O9: =VLOOKUP(C9,Looker!$1:$1048576,10,FALSE) -> 0 | P9: =VLOOKUP(C9,Dataflow!$1:$1048576,10,FALSE) -> 0 | Q9: =VLOOKUP(C9,Dataproc!$1:$1048576,10,FALSE) -> 0 | R9: =VLOOKUP(C9,'Google Kubernetes Engine'!$1:$1048576,10,FALSE) -> 0 | S9: =VLOOKUP(C9,'Apigee API Management'!$1:$1048576,10,FALSE) -> 0 | T9: =VLOOKUP(C9,'Cloud Run'!$1:$1048576,10,FALSE) -> 0 | U9: =VLOOKUP(C9,Workspace!$1:$1048576,10,FALSE) -> 0 | V9: =VLOOKUP(C9,'Cloud SQL'!$1:$1048576,10,FALSE) -> 0 | W9: =VLOOKUP(C9,'AlloyDB for PostgreSQL'!$1:$1048576,10,FALSE) -> 0 | X9: =VLOOKUP(C9,Spanner!$1:$1048576,10,FALSE) -> 0 | Y9: =VLOOKUP(C9,Oracle!$1:$1048576,10,FALSE) -> 0 | Z9: =VLOOKUP(C9,'Google Compute Engine'!$1:$1048576,10,FALSE) -> 0 | AA9: =VLOOKUP(C9,'Google Cloud Networking'!$1:$1048576,10,FALSE) -> 0 | AB9: =VLOOKUP(C9,'SAP on Google Cloud'!$1:$1048576,10,FALSE) -> 0 | AC9: =VLOOKUP(C9,'Google Cloud VMware Engine'!$1:$1048576,10,FALSE) -> 0 | AD9: =VLOOKUP(C9,'Google Distributed Cloud'!$1:$1048576,10,FALSE) -> 0 | AE9: =VLOOKUP(C9,'Cloud Security'!$1:$1048576,10,FALSE) -> 0 | AF9: =VLOOKUP(C9,'Security Command Center'!$1:$1048576,10,FALSE) -> 0 | AG9: =VLOOKUP(C9,'Security Operations'!$1:$1048576,10,FALSE) -> 0 | AH9: =VLOOKUP(C9,'Google Threat Intelligence'!$1:$1048576,10,FALSE) -> 0 | AI9: =VLOOKUP(C9,'Vertex AI Platform'!$1:$1048576,10,FALSE) -> 0 | AJ9: =VLOOKUP(C9,'AI Applications'!$1:$1048576,10,FALSE) -> 0 | AK9: =VLOOKUP(C9,'Gemini Enterprise'!$1:$1048576,10,FALSE) -> 0 | AL9: =VLOOKUP(C9,'Customer Engagement Suite'!$1:$1048576,10,FALSE) -> 0 | AM9: =SUM(N9:AL9) -> 0
A10: INC-13370 | B10: INC | C10: Arnav Sharma | D10: Principal Consultant | E10: L6 | F10: Rajat Singh | G10: CIDA-01 | H10: CIDA-01-2 | I10: Ops | J10: Data Scientist | K10: DS | L10: Arnav Sharma | N10: =VLOOKUP(C10,BigQuery!$1:$1048576,10,FALSE) -> 0 | O10: =VLOOKUP(C10,Looker!$1:$1048576,10,FALSE) -> 0 | P10: =VLOOKUP(C10,Dataflow!$1:$1048576,10,FALSE) -> 0 | Q10: =VLOOKUP(C10,Dataproc!$1:$1048576,10,FALSE) -> 0 | R10: =VLOOKUP(C10,'Google Kubernetes Engine'!$1:$1048576,10,FALSE) -> 0 | S10: =VLOOKUP(C10,'Apigee API Management'!$1:$1048576,10,FALSE) -> 0 | T10: =VLOOKUP(C10,'Cloud Run'!$1:$1048576,10,FALSE) -> 0 | U10: =VLOOKUP(C10,Workspace!$1:$1048576,10,FALSE) -> 0 | V10: =VLOOKUP(C10,'Cloud SQL'!$1:$1048576,10,FALSE) -> 0 | W10: =VLOOKUP(C10,'AlloyDB for PostgreSQL'!$1:$1048576,10,FALSE) -> 0 | X10: =VLOOKUP(C10,Spanner!$1:$1048576,10,FALSE) -> 0 | Y10: =VLOOKUP(C10,Oracle!$1:$1048576,10,FALSE) -> 0 | Z10: =VLOOKUP(C10,'Google Compute Engine'!$1:$1048576,10,FALSE) -> 0 | AA10: =VLOOKUP(C10,'Google Cloud Networking'!$1:$1048576,10,FALSE) -> 0 | AB10: =VLOOKUP(C10,'SAP on Google Cloud'!$1:$1048576,10,FALSE) -> 0 | AC10: =VLOOKUP(C10,'Google Cloud VMware Engine'!$1:$1048576,10,FALSE) -> 0 | AD10: =VLOOKUP(C10,'Google Distributed Cloud'!$1:$1048576,10,FALSE) -> 0 | AE10: =VLOOKUP(C10,'Cloud Security'!$1:$1048576,10,FALSE) -> 0 | AF10: =VLOOKUP(C10,'Security Command Center'!$1:$1048576,10,FALSE) -> 0 | AG10: =VLOOKUP(C10,'Security Operations'!$1:$1048576,10,FALSE) -> 0 | AH10: =VLOOKUP(C10,'Google Threat Intelligence'!$1:$1048576,10,FALSE) -> 0 | AI10: =VLOOKUP(C10,'Vertex AI Platform'!$1:$1048576,10,FALSE) -> 10 | AJ10: =VLOOKUP(C10,'AI Applications'!$1:$1048576,10,FALSE) -> 0 | AK10: =VLOOKUP(C10,'Gemini Enterprise'!$1:$1048576,10,FALSE) -> 0 | AL10: =VLOOKUP(C10,'Customer Engagement Suite'!$1:$1048576,10,FALSE) -> 0 | AM10: =SUM(N10:AL10) -> 10
A11: CHI-19693 | B11: CHI | C11: Arturo Pantoja | D11: Analyst | E11: L2 | F11: Brian Mackenzie | G11: CIDA-01 | H11: CIDA-01-1 | I11: Ops | J11: Data Engineer | K11: DE | L11: Venkatesh Coimbatore Kannan | N11: =VLOOKUP(C11,BigQuery!$1:$1048576,10,FALSE) -> 0 | O11: =VLOOKUP(C11,Looker!$1:$1048576,10,FALSE) -> 0 | P11: =VLOOKUP(C11,Dataflow!$1:$1048576,10,FALSE) -> 0 | Q11: =VLOOKUP(C11,Dataproc!$1:$1048576,10,FALSE) -> 0 | R11: =VLOOKUP(C11,'Google Kubernetes Engine'!$1:$1048576,10,FALSE) -> 0 | S11: =VLOOKUP(C11,'Apigee API Management'!$1:$1048576,10,FALSE) -> 0 | T11: =VLOOKUP(C11,'Cloud Run'!$1:$1048576,10,FALSE) -> 0 | U11: =VLOOKUP(C11,Workspace!$1:$1048576,10,FALSE) -> 0 | V11: =VLOOKUP(C11,'Cloud SQL'!$1:$1048576,10,FALSE) -> 0 | W11: =VLOOKUP(C11,'AlloyDB for PostgreSQL'!$1:$1048576,10,FALSE) -> 0 | X11: =VLOOKUP(C11,Spanner!$1:$1048576,10,FALSE) -> 0 | Y11: =VLOOKUP(C11,Oracle!$1:$1048576,10,FALSE) -> 0 | Z11: =VLOOKUP(C11,'Google Compute Engine'!$1:$1048576,10,FALSE) -> 0 | AA11: =VLOOKUP(C11,'Google Cloud Networking'!$1:$1048576,10,FALSE) -> 0 | AB11: =VLOOKUP(C11,'SAP on Google Cloud'!$1:$1048576,10,FALSE) -> 0 | AC11: =VLOOKUP(C11,'Google Cloud VMware Engine'!$1:$1048576,10,FALSE) -> 0 | AD11: =VLOOKUP(C11,'Google Distributed Cloud'!$1:$1048576,10,FALSE) -> 0 | AE11: =VLOOKUP(C11,'Cloud Security'!$1:$1048576,10,FALSE) -> 0 | AF11: =VLOOKUP(C11,'Security Command Center'!$1:$1048576,10,FALSE) -> 0 | AG11: =VLOOKUP(C11,'Security Operations'!$1:$1048576,10,FALSE) -> 0 | AH11: =VLOOKUP(C11,'Google Threat Intelligence'!$1:$1048576,10,FALSE) -> 0 | AI11: =VLOOKUP(C11,'Vertex AI Platform'!$1:$1048576,10,FALSE) -> 0 | AJ11: =VLOOKUP(C11,'AI Applications'!$1:$1048576,10,FALSE) -> 0 | AK11: =VLOOKUP(C11,'Gemini Enterprise'!$1:$1048576,10,FALSE) -> 0 | AL11: =VLOOKUP(C11,'Customer Engagement Suite'!$1:$1048576,10,FALSE) -> #N/A | AM11: =SUM(N11:AL11) -> #N/A
A12: CHI-15605 | B12: CHI | C12: Benja Appel | D12: Senior Engineer | E12: L3 | F12: Orlando Patino | G12: CIDA-01 | H12: CIDA-01-6 | I12: Ops | J12: Full Stack Developer | K12: SD | L12: Walter Paredes | M12: Professional Cloud DevOps Engineer | N12: =VLOOKUP(C12,BigQuery!$1:$1048576,10,FALSE) -> 0 | O12: =VLOOKUP(C12,Looker!$1:$1048576,10,FALSE) -> 0 | P12: =VLOOKUP(C12,Dataflow!$1:$1048576,10,FALSE) -> 0 | Q12: =VLOOKUP(C12,Dataproc!$1:$1048576,10,FALSE) -> 0 | R12: =VLOOKUP(C12,'Google Kubernetes Engine'!$1:$1048576,10,FALSE) -> 0 | S12: =VLOOKUP(C12,'Apigee API Management'!$1:$1048576,10,FALSE) -> 0 | T12: =VLOOKUP(C12,'Cloud Run'!$1:$1048576,10,FALSE) -> 9 | U12: =VLOOKUP(C12,Workspace!$1:$1048576,10,FALSE) -> 0 | V12: =VLOOKUP(C12,'Cloud SQL'!$1:$1048576,10,FALSE) -> 9 | W12: =VLOOKUP(C12,'AlloyDB for PostgreSQL'!$1:$1048576,10,FALSE) -> 0 | X12: =VLOOKUP(C12,Spanner!$1:$1048576,10,FALSE) -> 0 | Y12: =VLOOKUP(C12,Oracle!$1:$1048576,10,FALSE) -> 0 | Z12: =VLOOKUP(C12,'Google Compute Engine'!$1:$1048576,10,FALSE) -> 0 | AA12: =VLOOKUP(C12,'Google Cloud Networking'!$1:$1048576,10,FALSE) -> 0 | AB12: =VLOOKUP(C12,'SAP on Google Cloud'!$1:$1048576,10,FALSE) -> 0 | AC12: =VLOOKUP(C12,'Google Cloud VMware Engine'!$1:$1048576,10,FALSE) -> 0 | AD12: =VLOOKUP(C12,'Google Distributed Cloud'!$1:$1048576,10,FALSE) -> 0 | AE12: =VLOOKUP(C12,'Cloud Security'!$1:$1048576,10,FALSE) -> 0 | AF12: =VLOOKUP(C12,'Security Command Center'!$1:$1048576,10,FALSE) -> 0 | AG12: =VLOOKUP(C12,'Security Operations'!$1:$1048576,10,FALSE) -> 0 | AH12: =VLOOKUP(C12,'Google Threat Intelligence'!$1:$1048576,10,FALSE) -> 0 | AI12: =VLOOKUP(C12,'Vertex AI Platform'!$1:$1048576,10,FALSE) -> 0 | AJ12: =VLOOKUP(C12,'AI Applications'!$1:$1048576,10,FALSE) -> 0 | AK12: =VLOOKUP(C12,'Gemini Enterprise'!$1:$1048576,10,FALSE) -> 0 | AL12: =VLOOKUP(C12,'Customer Engagement Suite'!$1:$1048576,10,FALSE) -> 0 | AM12: =SUM(N12:AL12) -> 18
A13: COL-21960 | B13: COL | C13: Brayan Triana | D13: Senior Analyst | E13: L3 | F13: Marcelo Pimentel | G13: CIDA-01 | H13: CIDA-01-1 | I13: Ops | J13: Data Engineer | K13: DE | L13: Venkatesh Coimbatore Kannan | N13: =VLOOKUP(C13,BigQuery!$1:$1048576,10,FALSE) -> 18 | O13: =VLOOKUP(C13,Looker!$1:$1048576,10,FALSE) -> 0 | P13: =VLOOKUP(C13,Dataflow!$1:$1048576,10,FALSE) -> 18 | Q13: =VLOOKUP(C13,Dataproc!$1:$1048576,10,FALSE) -> 8 | R13: =VLOOKUP(C13,'Google Kubernetes Engine'!$1:$1048576,10,FALSE) -> 0 | S13: =VLOOKUP(C13,'Apigee API Management'!$1:$1048576,10,FALSE) -> 0 | T13: =VLOOKUP(C13,'Cloud Run'!$1:$1048576,10,FALSE) -> 0 | U13: =VLOOKUP(C13,Workspace!$1:$1048576,10,FALSE) -> 0 | V13: =VLOOKUP(C13,'Cloud SQL'!$1:$1048576,10,FALSE) -> 0 | W13: =VLOOKUP(C13,'AlloyDB for PostgreSQL'!$1:$1048576,10,FALSE) -> 0 | X13: =VLOOKUP(C13,Spanner!$1:$1048576,10,FALSE) -> 0 | Y13: =VLOOKUP(C13,Oracle!$1:$1048576,10,FALSE) -> 0 | Z13: =VLOOKUP(C13,'Google Compute Engine'!$1:$1048576,10,FALSE) -> 0 | AA13: =VLOOKUP(C13,'Google Cloud Networking'!$1:$1048576,10,FALSE) -> 0 | AB13: =VLOOKUP(C13,'SAP on Google Cloud'!$1:$1048576,10,FALSE) -> 0 | AC13: =VLOOKUP(C13,'Google Cloud VMware Engine'!$1:$1048576,10,FALSE) -> 0 | AD13: =VLOOKUP(C13,'Google Distributed Cloud'!$1:$1048576,10,FALSE) -> 0 | AE13: =VLOOKUP(C13,'Cloud Security'!$1:$1048576,10,FALSE) -> 0 | AF13: =VLOOKUP(C13,'Security Command Center'!$1:$1048576,10,FALSE) -> 0 | AG13: =VLOOKUP(C13,'Security Operations'!$1:$1048576,10,FALSE) -> 0 | AH13: =VLOOKUP(C13,'Google Threat Intelligence'!$1:$1048576,10,FALSE) -> 0 | AI13: =VLOOKUP(C13,'Vertex AI Platform'!$1:$1048576,10,FALSE) -> 0 | AJ13: =VLOOKUP(C13,'AI Applications'!$1:$1048576,10,FALSE) -> 0 | AK13: =VLOOKUP(C13,'Gemini Enterprise'!$1:$1048576,10,FALSE) -> 0 | AL13: =VLOOKUP(C13,'Customer Engagement Suite'!$1:$1048576,10,FALSE) -> 0 | AM13: =SUM(N13:AL13) -> 44
A14: CHI-18242 | B14: CHI | C14: Brian Mackenzie | D14: Senior Consultant | E14: L5 | F14: Diego Cordova | G14: CIDA-01 | H14: CIDA-01-1 | I14: Ops | J14: BI Developer | K14: DE | L14: Venkatesh Coimbatore Kannan | N14: =VLOOKUP(C14,BigQuery!$1:$1048576,10,FALSE) -> 0 | O14: =VLOOKUP(C14,Looker!$1:$1048576,10,FALSE) -> 0 | P14: =VLOOKUP(C14,Dataflow!$1:$1048576,10,FALSE) -> 0 | Q14: =VLOOKUP(C14,Dataproc!$1:$1048576,10,FALSE) -> 0 | R14: =VLOOKUP(C14,'Google Kubernetes Engine'!$1:$1048576,10,FALSE) -> 0 | S14: =VLOOKUP(C14,'Apigee API Management'!$1:$1048576,10,FALSE) -> 0 | T14: =VLOOKUP(C14,'Cloud Run'!$1:$1048576,10,FALSE) -> 0 | U14: =VLOOKUP(C14,Workspace!$1:$1048576,10,FALSE) -> 0 | V14: =VLOOKUP(C14,'Cloud SQL'!$1:$1048576,10,FALSE) -> 0 | W14: =VLOOKUP(C14,'AlloyDB for PostgreSQL'!$1:$1048576,10,FALSE) -> 0 | X14: =VLOOKUP(C14,Spanner!$1:$1048576,10,FALSE) -> 0 | Y14: =VLOOKUP(C14,Oracle!$1:$1048576,10,FALSE) -> 0 | Z14: =VLOOKUP(C14,'Google Compute Engine'!$1:$1048576,10,FALSE) -> 0 | AA14: =VLOOKUP(C14,'Google Cloud Networking'!$1:$1048576,10,FALSE) -> 0 | AB14: =VLOOKUP(C14,'SAP on Google Cloud'!$1:$1048576,10,FALSE) -> 0 | AC14: =VLOOKUP(C14,'Google Cloud VMware Engine'!$1:$1048576,10,FALSE) -> 0 | AD14: =VLOOKUP(C14,'Google Distributed Cloud'!$1:$1048576,10,FALSE) -> 0 | AE14: =VLOOKUP(C14,'Cloud Security'!$1:$1048576,10,FALSE) -> 0 | AF14: =VLOOKUP(C14,'Security Command Center'!$1:$1048576,10,FALSE) -> 0 | AG14: =VLOOKUP(C14,'Security Operations'!$1:$1048576,10,FALSE) -> 0 | AH14: =VLOOKUP(C14,'Google Threat Intelligence'!$1:$1048576,10,FALSE) -> 0 | AI14: =VLOOKUP(C14,'Vertex AI Platform'!$1:$1048576,10,FALSE) -> 0 | AJ14: =VLOOKUP(C14,'AI Applications'!$1:$1048576,10,FALSE) -> 0 | AK14: =VLOOKUP(C14,'Gemini Enterprise'!$1:$1048576,10,FALSE) -> 0 | AL14: =VLOOKUP(C14,'Customer Engagement Suite'!$1:$1048576,10,FALSE) -> 0 | AM14: =SUM(N14:AL14) -> 0
A15: CHI-16338 | B15: CHI | C15: Bruno Rodríguez | D15: Senior Engineer | E15: L3 | F15: Maria Ramirez | G15: CIDA-01 | H15: CIDA-01-6 | I15: Ops | J15: Full Stack Developer | K15: SD | L15: Walter Paredes | M15: Professional Cloud Developer | N15: =VLOOKUP(C15,BigQuery!$1:$1048576,10,FALSE) -> 0 | O15: =VLOOKUP(C15,Looker!$1:$1048576,10,FALSE) -> 0 | P15: =VLOOKUP(C15,Dataflow!$1:$1048576,10,FALSE) -> 0 | Q15: =VLOOKUP(C15,Dataproc!$1:$1048576,10,FALSE) -> 0 | R15: =VLOOKUP(C15,'Google Kubernetes Engine'!$1:$1048576,10,FALSE) -> 5 | S15: =VLOOKUP(C15,'Apigee API Management'!$1:$1048576,10,FALSE) -> 0 | T15: =VLOOKUP(C15,'Cloud Run'!$1:$1048576,10,FALSE) -> 5 | U15: =VLOOKUP(C15,Workspace!$1:$1048576,10,FALSE) -> 0 | V15: =VLOOKUP(C15,'Cloud SQL'!$1:$1048576,10,FALSE) -> 0 | W15: =VLOOKUP(C15,'AlloyDB for PostgreSQL'!$1:$1048576,10,FALSE) -> 0 | X15: =VLOOKUP(C15,Spanner!$1:$1048576,10,FALSE) -> 0 | Y15: =VLOOKUP(C15,Oracle!$1:$1048576,10,FALSE) -> 0 | Z15: =VLOOKUP(C15,'Google Compute Engine'!$1:$1048576,10,FALSE) -> 0 | AA15: =VLOOKUP(C15,'Google Cloud Networking'!$1:$1048576,10,FALSE) -> 0 | AB15: =VLOOKUP(C15,'SAP on Google Cloud'!$1:$1048576,10,FALSE) -> 0 | AC15: =VLOOKUP(C15,'Google Cloud VMware Engine'!$1:$1048576,10,FALSE) -> 0 | AD15: =VLOOKUP(C15,'Google Distributed Cloud'!$1:$1048576,10,FALSE) -> 0 | AE15: =VLOOKUP(C15,'Cloud Security'!$1:$1048576,10,FALSE) -> 0 | AF15: =VLOOKUP(C15,'Security Command Center'!$1:$1048576,10,FALSE) -> 0 | AG15: =VLOOKUP(C15,'Security Operations'!$1:$1048576,10,FALSE) -> 0 | AH15: =VLOOKUP(C15,'Google Threat Intelligence'!$1:$1048576,10,FALSE) -> 0 | AI15: =VLOOKUP(C15,'Vertex AI Platform'!$1:$1048576,10,FALSE) -> 0 | AJ15: =VLOOKUP(C15,'AI Applications'!$1:$1048576,10,FALSE) -> 0 | AK15: =VLOOKUP(C15,'Gemini Enterprise'!$1:$1048576,10,FALSE) -> 0 | AL15: =VLOOKUP(C15,'Customer Engagement Suite'!$1:$1048576,10,FALSE) -> 0 | AM15: =SUM(N15:AL15) -> 10
A16: CAN-21345 | B16: CAN | C16: Camila Da Silveira | D16: Consultant | E16: L4 | F16: Venkatesh Kannan | G16: CIDA-05 | H16: CIDA-05-1 | I16: Ops | J16: Data Engineer | K16: DE | L16: Venkatesh Coimbatore Kannan | N16: =VLOOKUP(C16,BigQuery!$1:$1048576,10,FALSE) -> 0 | O16: =VLOOKUP(C16,Looker!$1:$1048576,10,FALSE) -> 14 | P16: =VLOOKUP(C16,Dataflow!$1:$1048576,10,FALSE) -> 0 | Q16: =VLOOKUP(C16,Dataproc!$1:$1048576,10,FALSE) -> 0 | R16: =VLOOKUP(C16,'Google Kubernetes Engine'!$1:$1048576,10,FALSE) -> 0 | S16: =VLOOKUP(C16,'Apigee API Management'!$1:$1048576,10,FALSE) -> 0 | T16: =VLOOKUP(C16,'Cloud Run'!$1:$1048576,10,FALSE) -> 0 | U16: =VLOOKUP(C16,Workspace!$1:$1048576,10,FALSE) -> 0 | V16: =VLOOKUP(C16,'Cloud SQL'!$1:$1048576,10,FALSE) -> 0 | W16: =VLOOKUP(C16,'AlloyDB for PostgreSQL'!$1:$1048576,10,FALSE) -> 0 | X16: =VLOOKUP(C16,Spanner!$1:$1048576,10,FALSE) -> 0 | Y16: =VLOOKUP(C16,Oracle!$1:$1048576,10,FALSE) -> 0 | Z16: =VLOOKUP(C16,'Google Compute Engine'!$1:$1048576,10,FALSE) -> 14 | AA16: =VLOOKUP(C16,'Google Cloud Networking'!$1:$1048576,10,FALSE) -> 0 | AB16: =VLOOKUP(C16,'SAP on Google Cloud'!$1:$1048576,10,FALSE) -> 14 | AC16: =VLOOKUP(C16,'Google Cloud VMware Engine'!$1:$1048576,10,FALSE) -> 14 | AD16: =VLOOKUP(C16,'Google Distributed Cloud'!$1:$1048576,10,FALSE) -> 14 | AE16: =VLOOKUP(C16,'Cloud Security'!$1:$1048576,10,FALSE) -> 0 | AF16: =VLOOKUP(C16,'Security Command Center'!$1:$1048576,10,FALSE) -> 0 | AG16: =VLOOKUP(C16,'Security Operations'!$1:$1048576,10,FALSE) -> 0 | AH16: =VLOOKUP(C16,'Google Threat Intelligence'!$1:$1048576,10,FALSE) -> 0 | AI16: =VLOOKUP(C16,'Vertex AI Platform'!$1:$1048576,10,FALSE) -> 0 | AJ16: =VLOOKUP(C16,'AI Applications'!$1:$1048576,10,FALSE) -> 0 | AK16: =VLOOKUP(C16,'Gemini Enterprise'!$1:$1048576,10,FALSE) -> 0 | AL16: =VLOOKUP(C16,'Customer Engagement Suite'!$1:$1048576,10,FALSE) -> 0 | AM16: =SUM(N16:AL16) -> 70
A17: CHI-17853 | B17: CHI | C17: Carlos Fuensalida | D17: Senior Consultant | E17: L5 | F17: Kelly Sparks | G17: CIDA-01 | H17: CIDA-01-6 | I17: Ops | J17: DevOps Engineer | K17: SD | L17: Walter Paredes | M17: Professional Cloud DevOps Engineer | N17: =VLOOKUP(C17,BigQuery!$1:$1048576,10,FALSE) -> 0 | O17: =VLOOKUP(C17,Looker!$1:$1048576,10,FALSE) -> 0 | P17: =VLOOKUP(C17,Dataflow!$1:$1048576,10,FALSE) -> 0 | Q17: =VLOOKUP(C17,Dataproc!$1:$1048576,10,FALSE) -> 0 | R17: =VLOOKUP(C17,'Google Kubernetes Engine'!$1:$1048576,10,FALSE) -> 0 | S17: =VLOOKUP(C17,'Apigee API Management'!$1:$1048576,10,FALSE) -> 0 | T17: =VLOOKUP(C17,'Cloud Run'!$1:$1048576,10,FALSE) -> 0 | U17: =VLOOKUP(C17,Workspace!$1:$1048576,10,FALSE) -> 0 | V17: =VLOOKUP(C17,'Cloud SQL'!$1:$1048576,10,FALSE) -> 0 | W17: =VLOOKUP(C17,'AlloyDB for PostgreSQL'!$1:$1048576,10,FALSE) -> 0 | X17: =VLOOKUP(C17,Spanner!$1:$1048576,10,FALSE) -> 0 | Y17: =VLOOKUP(C17,Oracle!$1:$1048576,10,FALSE) -> 0 | Z17: =VLOOKUP(C17,'Google Compute Engine'!$1:$1048576,10,FALSE) -> 0 | AA17: =VLOOKUP(C17,'Google Cloud Networking'!$1:$1048576,10,FALSE) -> 0 | AB17: =VLOOKUP(C17,'SAP on Google Cloud'!$1:$1048576,10,FALSE) -> 0 | AC17: =VLOOKUP(C17,'Google Cloud VMware Engine'!$1:$1048576,10,FALSE) -> 0 | AD17: =VLOOKUP(C17,'Google Distributed Cloud'!$1:$1048576,10,FALSE) -> 0 | AE17: =VLOOKUP(C17,'Cloud Security'!$1:$1048576,10,FALSE) -> 0 | AF17: =VLOOKUP(C17,'Security Command Center'!$1:$1048576,10,FALSE) -> 0 | AG17: =VLOOKUP(C17,'Security Operations'!$1:$1048576,10,FALSE) -> 0 | AH17: =VLOOKUP(C17,'Google Threat Intelligence'!$1:$1048576,10,FALSE) -> 0 | AI17: =VLOOKUP(C17,'Vertex AI Platform'!$1:$1048576,10,FALSE) -> 0 | AJ17: =VLOOKUP(C17,'AI Applications'!$1:$1048576,10,FALSE) -> 0 | AK17: =VLOOKUP(C17,'Gemini Enterprise'!$1:$1048576,10,FALSE) -> 0 | AL17: =VLOOKUP(C17,'Customer Engagement Suite'!$1:$1048576,10,FALSE) -> 0 | AM17: =SUM(N17:AL17) -> 0
A18: COL-21963 | B18: COL | C18: Carlos Llinas | D18: Senior Consultant | E18: L5 | F18: Jorge Ponce | G18: CIDA-01 | H18: CIDA-01-6 | I18: Ops | J18: Project Manager | K18: SD | L18: Walter Paredes | N18: =VLOOKUP(C18,BigQuery!$1:$1048576,10,FALSE) -> 0 | O18: =VLOOKUP(C18,Looker!$1:$1048576,10,FALSE) -> 0 | P18: =VLOOKUP(C18,Dataflow!$1:$1048576,10,FALSE) -> 0 | Q18: =VLOOKUP(C18,Dataproc!$1:$1048576,10,FALSE) -> 0 | R18: =VLOOKUP(C18,'Google Kubernetes Engine'!$1:$1048576,10,FALSE) -> 0 | S18: =VLOOKUP(C18,'Apigee API Management'!$1:$1048576,10,FALSE) -> 0 | T18: =VLOOKUP(C18,'Cloud Run'!$1:$1048576,10,FALSE) -> 0 | U18: =VLOOKUP(C18,Workspace!$1:$1048576,10,FALSE) -> 0 | V18: =VLOOKUP(C18,'Cloud SQL'!$1:$1048576,10,FALSE) -> 0 | W18: =VLOOKUP(C18,'AlloyDB for PostgreSQL'!$1:$1048576,10,FALSE) -> 0 | X18: =VLOOKUP(C18,Spanner!$1:$1048576,10,FALSE) -> 0 | Y18: =VLOOKUP(C18,Oracle!$1:$1048576,10,FALSE) -> 0 | Z18: =VLOOKUP(C18,'Google Compute Engine'!$1:$1048576,10,FALSE) -> 0 | AA18: =VLOOKUP(C18,'Google Cloud Networking'!$1:$1048576,10,FALSE) -> 0 | AB18: =VLOOKUP(C18,'SAP on Google Cloud'!$1:$1048576,10,FALSE) -> 0 | AC18: =VLOOKUP(C18,'Google Cloud VMware Engine'!$1:$1048576,10,FALSE) -> 0 | AD18: =VLOOKUP(C18,'Google Distributed Cloud'!$1:$1048576,10,FALSE) -> 0 | AE18: =VLOOKUP(C18,'Cloud Security'!$1:$1048576,10,FALSE) -> 0 | AF18: =VLOOKUP(C18,'Security Command Center'!$1:$1048576,10,FALSE) -> 0 | AG18: =VLOOKUP(C18,'Security Operations'!$1:$1048576,10,FALSE) -> 0 | AH18: =VLOOKUP(C18,'Google Threat Intelligence'!$1:$1048576,10,FALSE) -> 0 | AI18: =VLOOKUP(C18,'Vertex AI Platform'!$1:$1048576,10,FALSE) -> 0 | AJ18: =VLOOKUP(C18,'AI Applications'!$1:$1048576,10,FALSE) -> 0 | AK18: =VLOOKUP(C18,'Gemini Enterprise'!$1:$1048576,10,FALSE) -> 0 | AL18: =VLOOKUP(C18,'Customer Engagement Suite'!$1:$1048576,10,FALSE) -> 0 | AM18: =SUM(N18:AL18) -> 0
A19: CHI-14952 | B19: CHI | C19: Carolina Aspee | D19: Senior Analyst | E19: L3 | F19: Brian Mackenzie | G19: CIDA-01 | H19: CIDA-01-4 | I19: Ops | J19: BI Developer | K19: DE | L19: Venkatesh Coimbatore Kannan | N19: =VLOOKUP(C19,BigQuery!$1:$1048576,10,FALSE) -> #N/A | O19: =VLOOKUP(C19,Looker!$1:$1048576,10,FALSE) -> #N/A | P19: =VLOOKUP(C19,Dataflow!$1:$1048576,10,FALSE) -> #N/A | Q19: =VLOOKUP(C19,Dataproc!$1:$1048576,10,FALSE) -> #N/A | R19: =VLOOKUP(C19,'Google Kubernetes Engine'!$1:$1048576,10,FALSE) -> #N/A | S19: =VLOOKUP(C19,'Apigee API Management'!$1:$1048576,10,FALSE) -> #N/A | T19: =VLOOKUP(C19,'Cloud Run'!$1:$1048576,10,FALSE) -> #N/A | U19: =VLOOKUP(C19,Workspace!$1:$1048576,10,FALSE) -> #N/A | V19: =VLOOKUP(C19,'Cloud SQL'!$1:$1048576,10,FALSE) -> #N/A | W19: =VLOOKUP(C19,'AlloyDB for PostgreSQL'!$1:$1048576,10,FALSE) -> #N/A | X19: =VLOOKUP(C19,Spanner!$1:$1048576,10,FALSE) -> #N/A | Y19: =VLOOKUP(C19,Oracle!$1:$1048576,10,FALSE) -> #N/A | Z19: =VLOOKUP(C19,'Google Compute Engine'!$1:$1048576,10,FALSE) -> #N/A | AA19: =VLOOKUP(C19,'Google Cloud Networking'!$1:$1048576,10,FALSE) -> #N/A | AB19: =VLOOKUP(C19,'SAP on Google Cloud'!$1:$1048576,10,FALSE) -> #N/A | AC19: =VLOOKUP(C19,'Google Cloud VMware Engine'!$1:$1048576,10,FALSE) -> #N/A | AD19: =VLOOKUP(C19,'Google Distributed Cloud'!$1:$1048576,10,FALSE) -> #N/A | AE19: =VLOOKUP(C19,'Cloud Security'!$1:$1048576,10,FALSE) -> #N/A | AF19: =VLOOKUP(C19,'Security Command Center'!$1:$1048576,10,FALSE) -> #N/A | AG19: =VLOOKUP(C19,'Security Operations'!$1:$1048576,10,FALSE) -> #N/A | AH19: =VLOOKUP(C19,'Google Threat Intelligence'!$1:$1048576,10,FALSE) -> #N/A | AI19: =VLOOKUP(C19,'Vertex AI Platform'!$1:$1048576,10,FALSE) -> #N/A | AJ19: =VLOOKUP(C19,'AI Applications'!$1:$1048576,10,FALSE) -> #N/A | AK19: =VLOOKUP(C19,'Gemini Enterprise'!$1:$1048576,10,FALSE) -> #N/A | AL19: =VLOOKUP(C19,'Customer Engagement Suite'!$1:$1048576,10,FALSE) -> #N/A | AM19: =SUM(N19:AL19) -> #N/A
A20: CHI-17264 | B20: CHI | C20: Celia Riquelme | D20: Senior Analyst | E20: L3 | F20: Julio Verdugo | G20: CIDA-01 | H20: CIDA-01-4 | I20: Ops | J20: BI Developer | K20: BI | L20: Walter Paredes | N20: =VLOOKUP(C20,BigQuery!$1:$1048576,10,FALSE) -> #N/A | O20: =VLOOKUP(C20,Looker!$1:$1048576,10,FALSE) -> #N/A | P20: =VLOOKUP(C20,Dataflow!$1:$1048576,10,FALSE) -> #N/A | Q20: =VLOOKUP(C20,Dataproc!$1:$1048576,10,FALSE) -> #N/A | R20: =VLOOKUP(C20,'Google Kubernetes Engine'!$1:$1048576,10,FALSE) -> #N/A | S20: =VLOOKUP(C20,'Apigee API Management'!$1:$1048576,10,FALSE) -> #N/A | T20: =VLOOKUP(C20,'Cloud Run'!$1:$1048576,10,FALSE) -> #N/A | U20: =VLOOKUP(C20,Workspace!$1:$1048576,10,FALSE) -> #N/A | V20: =VLOOKUP(C20,'Cloud SQL'!$1:$1048576,10,FALSE) -> #N/A | W20: =VLOOKUP(C20,'AlloyDB for PostgreSQL'!$1:$1048576,10,FALSE) -> #N/A | X20: =VLOOKUP(C20,Spanner!$1:$1048576,10,FALSE) -> #N/A | Y20: =VLOOKUP(C20,Oracle!$1:$1048576,10,FALSE) -> #N/A | Z20: =VLOOKUP(C20,'Google Compute Engine'!$1:$1048576,10,FALSE) -> #N/A | AA20: =VLOOKUP(C20,'Google Cloud Networking'!$1:$1048576,10,FALSE) -> #N/A | AB20: =VLOOKUP(C20,'SAP on Google Cloud'!$1:$1048576,10,FALSE) -> #N/A | AC20: =VLOOKUP(C20,'Google Cloud VMware Engine'!$1:$1048576,10,FALSE) -> #N/A | AD20: =VLOOKUP(C20,'Google Distributed Cloud'!$1:$1048576,10,FALSE) -> #N/A | AE20: =VLOOKUP(C20,'Cloud Security'!$1:$1048576,10,FALSE) -> #N/A | AF20: =VLOOKUP(C20,'Security Command Center'!$1:$1048576,10,FALSE) -> #N/A | AG20: =VLOOKUP(C20,'Security Operations'!$1:$1048576,10,FALSE) -> #N/A | AH20: =VLOOKUP(C20,'Google Threat Intelligence'!$1:$1048576,10,FALSE) -> #N/A | AI20: =VLOOKUP(C20,'Vertex AI Platform'!$1:$1048576,10,FALSE) -> #N/A | AJ20: =VLOOKUP(C20,'AI Applications'!$1:$1048576,10,FALSE) -> #N/A | AK20: =VLOOKUP(C20,'Gemini Enterprise'!$1:$1048576,10,FALSE) -> #N/A | AL20: =VLOOKUP(C20,'Customer Engagement Suite'!$1:$1048576,10,FALSE) -> #N/A | AM20: =SUM(N20:AL20) -> #N/A
A21: INC-23760 | B21: INC | C21: Christiane Marie Liliane Fortin | D21: Consultant | E21: L4 | F21: Kelly Sparks | G21: CIDA-05 | H21: CIDA-05-6 | I21: Ops | J21: Business Systems Analyst | K21: SD | L21: Walter Paredes | N21: =VLOOKUP(C21,BigQuery!$1:$1048576,10,FALSE) -> #N/A | O21: =VLOOKUP(C21,Looker!$1:$1048576,10,FALSE) -> #N/A | P21: =VLOOKUP(C21,Dataflow!$1:$1048576,10,FALSE) -> #N/A | Q21: =VLOOKUP(C21,Dataproc!$1:$1048576,10,FALSE) -> #N/A | R21: =VLOOKUP(C21,'Google Kubernetes Engine'!$1:$1048576,10,FALSE) -> #N/A | S21: =VLOOKUP(C21,'Apigee API Management'!$1:$1048576,10,FALSE) -> #N/A | T21: =VLOOKUP(C21,'Cloud Run'!$1:$1048576,10,FALSE) -> #N/A | U21: =VLOOKUP(C21,Workspace!$1:$1048576,10,FALSE) -> #N/A | V21: =VLOOKUP(C21,'Cloud SQL'!$1:$1048576,10,FALSE) -> #N/A | W21: =VLOOKUP(C21,'AlloyDB for PostgreSQL'!$1:$1048576,10,FALSE) -> #N/A | X21: =VLOOKUP(C21,Spanner!$1:$1048576,10,FALSE) -> #N/A | Y21: =VLOOKUP(C21,Oracle!$1:$1048576,10,FALSE) -> #N/A | Z21: =VLOOKUP(C21,'Google Compute Engine'!$1:$1048576,10,FALSE) -> #N/A | AA21: =VLOOKUP(C21,'Google Cloud Networking'!$1:$1048576,10,FALSE) -> #N/A | AB21: =VLOOKUP(C21,'SAP on Google Cloud'!$1:$1048576,10,FALSE) -> #N/A | AC21: =VLOOKUP(C21,'Google Cloud VMware Engine'!$1:$1048576,10,FALSE) -> #N/A | AD21: =VLOOKUP(C21,'Google Distributed Cloud'!$1:$1048576,10,FALSE) -> #N/A | AE21: =VLOOKUP(C21,'Cloud Security'!$1:$1048576,10,FALSE) -> #N/A | AF21: =VLOOKUP(C21,'Security Command Center'!$1:$1048576,10,FALSE) -> #N/A | AG21: =VLOOKUP(C21,'Security Operations'!$1:$1048576,10,FALSE) -> #N/A | AH21: =VLOOKUP(C21,'Google Threat Intelligence'!$1:$1048576,10,FALSE) -> #N/A | AI21: =VLOOKUP(C21,'Vertex AI Platform'!$1:$1048576,10,FALSE) -> #N/A | AJ21: =VLOOKUP(C21,'AI Applications'!$1:$1048576,10,FALSE) -> #N/A | AK21: =VLOOKUP(C21,'Gemini Enterprise'!$1:$1048576,10,FALSE) -> #N/A | AL21: =VLOOKUP(C21,'Customer Engagement Suite'!$1:$1048576,10,FALSE) -> #N/A | AM21: =SUM(N21:AL21) -> #N/A
A22: INC-18931 | B22: INC | C22: Clinton Pillsbury | D22: Associate Director | E22: L7 | F22: Walter Paredes | G22: CIDA-05 | H22: CIDA-05-6 | I22: Ops | J22: Full Stack Developer | K22: SD | L22: Walter Paredes | M22: Machine Learning Engineer | N22: =VLOOKUP(C22,BigQuery!$1:$1048576,10,FALSE) -> 0 | O22: =VLOOKUP(C22,Looker!$1:$1048576,10,FALSE) -> 0 | P22: =VLOOKUP(C22,Dataflow!$1:$1048576,10,FALSE) -> 0 | Q22: =VLOOKUP(C22,Dataproc!$1:$1048576,10,FALSE) -> 0 | R22: =VLOOKUP(C22,'Google Kubernetes Engine'!$1:$1048576,10,FALSE) -> 0 | S22: =VLOOKUP(C22,'Apigee API Management'!$1:$1048576,10,FALSE) -> 0 | T22: =VLOOKUP(C22,'Cloud Run'!$1:$1048576,10,FALSE) -> 0 | U22: =VLOOKUP(C22,Workspace!$1:$1048576,10,FALSE) -> 0 | V22: =VLOOKUP(C22,'Cloud SQL'!$1:$1048576,10,FALSE) -> 0 | W22: =VLOOKUP(C22,'AlloyDB for PostgreSQL'!$1:$1048576,10,FALSE) -> 0 | X22: =VLOOKUP(C22,Spanner!$1:$1048576,10,FALSE) -> 0 | Y22: =VLOOKUP(C22,Oracle!$1:$1048576,10,FALSE) -> 0 | Z22: =VLOOKUP(C22,'Google Compute Engine'!$1:$1048576,10,FALSE) -> 0 | AA22: =VLOOKUP(C22,'Google Cloud Networking'!$1:$1048576,10,FALSE) -> 0 | AB22: =VLOOKUP(C22,'SAP on Google Cloud'!$1:$1048576,10,FALSE) -> 0 | AC22: =VLOOKUP(C22,'Google Cloud VMware Engine'!$1:$1048576,10,FALSE) -> 0 | AD22: =VLOOKUP(C22,'Google Distributed Cloud'!$1:$1048576,10,FALSE) -> 0 | AE22: =VLOOKUP(C22,'Cloud Security'!$1:$1048576,10,FALSE) -> 0 | AF22: =VLOOKUP(C22,'Security Command Center'!$1:$1048576,10,FALSE) -> 0 | AG22: =VLOOKUP(C22,'Security Operations'!$1:$1048576,10,FALSE) -> 0 | AH22: =VLOOKUP(C22,'Google Threat Intelligence'!$1:$1048576,10,FALSE) -> 0 | AI22: =VLOOKUP(C22,'Vertex AI Platform'!$1:$1048576,10,FALSE) -> 0 | AJ22: =VLOOKUP(C22,'AI Applications'!$1:$1048576,10,FALSE) -> 0 | AK22: =VLOOKUP(C22,'Gemini Enterprise'!$1:$1048576,10,FALSE) -> 0 | AL22: =VLOOKUP(C22,'Customer Engagement Suite'!$1:$1048576,10,FALSE) -> 0 | AM22: =SUM(N22:AL22) -> 0
A23: CHI-17685 | B23: CHI | C23: Cristian Brauchy | D23: Senior Analyst | E23: L3 | F23: Gabriel Gajardo | G23: CIDA-01 | H23: CIDA-01-1 | I23: Ops | J23: BI Developer | K23: DE | L23: Venkatesh Coimbatore Kannan | N23: =VLOOKUP(C23,BigQuery!$1:$1048576,10,FALSE) -> 0 | O23: =VLOOKUP(C23,Looker!$1:$1048576,10,FALSE) -> 0 | P23: =VLOOKUP(C23,Dataflow!$1:$1048576,10,FALSE) -> 0 | Q23: =VLOOKUP(C23,Dataproc!$1:$1048576,10,FALSE) -> 0 | R23: =VLOOKUP(C23,'Google Kubernetes Engine'!$1:$1048576,10,FALSE) -> 0 | S23: =VLOOKUP(C23,'Apigee API Management'!$1:$1048576,10,FALSE) -> 0 | T23: =VLOOKUP(C23,'Cloud Run'!$1:$1048576,10,FALSE) -> 0 | U23: =VLOOKUP(C23,Workspace!$1:$1048576,10,FALSE) -> 0 | V23: =VLOOKUP(C23,'Cloud SQL'!$1:$1048576,10,FALSE) -> 0 | W23: =VLOOKUP(C23,'AlloyDB for PostgreSQL'!$1:$1048576,10,FALSE) -> 0 | X23: =VLOOKUP(C23,Spanner!$1:$1048576,10,FALSE) -> 0 | Y23: =VLOOKUP(C23,Oracle!$1:$1048576,10,FALSE) -> 0 | Z23: =VLOOKUP(C23,'Google Compute Engine'!$1:$1048576,10,FALSE) -> 0 | AA23: =VLOOKUP(C23,'Google Cloud Networking'!$1:$1048576,10,FALSE) -> 0 | AB23: =VLOOKUP(C23,'SAP on Google Cloud'!$1:$1048576,10,FALSE) -> 0 | AC23: =VLOOKUP(C23,'Google Cloud VMware Engine'!$1:$1048576,10,FALSE) -> 0 | AD23: =VLOOKUP(C23,'Google Distributed Cloud'!$1:$1048576,10,FALSE) -> 0 | AE23: =VLOOKUP(C23,'Cloud Security'!$1:$1048576,10,FALSE) -> 0 | AF23: =VLOOKUP(C23,'Security Command Center'!$1:$1048576,10,FALSE) -> 0 | AG23: =VLOOKUP(C23,'Security Operations'!$1:$1048576,10,FALSE) -> 0 | AH23: =VLOOKUP(C23,'Google Threat Intelligence'!$1:$1048576,10,FALSE) -> 0 | AI23: =VLOOKUP(C23,'Vertex AI Platform'!$1:$1048576,10,FALSE) -> 0 | AJ23: =VLOOKUP(C23,'AI Applications'!$1:$1048576,10,FALSE) -> 0 | AK23: =VLOOKUP(C23,'Gemini Enterprise'!$1:$1048576,10,FALSE) -> 0 | AL23: =VLOOKUP(C23,'Customer Engagement Suite'!$1:$1048576,10,FALSE) -> #N/A | AM23: =SUM(N23:AL23) -> #N/A
A24: CHI-11452 | B24: CHI | C24: Daniel Fuentes | D24: Consultant | E24: L4 | F24: Raman Bangalore Venkatakr | G24: CIDA-01 | H24: CIDA-01-4 | I24: Ops | J24: BI Developer | K24: BI | L24: Walter Paredes | N24: =VLOOKUP(C24,BigQuery!$1:$1048576,10,FALSE) -> 0 | O24: =VLOOKUP(C24,Looker!$1:$1048576,10,FALSE) -> 0 | P24: =VLOOKUP(C24,Dataflow!$1:$1048576,10,FALSE) -> 0 | Q24: =VLOOKUP(C24,Dataproc!$1:$1048576,10,FALSE) -> 0 | R24: =VLOOKUP(C24,'Google Kubernetes Engine'!$1:$1048576,10,FALSE) -> 0 | S24: =VLOOKUP(C24,'Apigee API Management'!$1:$1048576,10,FALSE) -> 0 | T24: =VLOOKUP(C24,'Cloud Run'!$1:$1048576,10,FALSE) -> 0 | U24: =VLOOKUP(C24,Workspace!$1:$1048576,10,FALSE) -> 0 | V24: =VLOOKUP(C24,'Cloud SQL'!$1:$1048576,10,FALSE) -> 0 | W24: =VLOOKUP(C24,'AlloyDB for PostgreSQL'!$1:$1048576,10,FALSE) -> 0 | X24: =VLOOKUP(C24,Spanner!$1:$1048576,10,FALSE) -> 0 | Y24: =VLOOKUP(C24,Oracle!$1:$1048576,10,FALSE) -> 0 | Z24: =VLOOKUP(C24,'Google Compute Engine'!$1:$1048576,10,FALSE) -> 0 | AA24: =VLOOKUP(C24,'Google Cloud Networking'!$1:$1048576,10,FALSE) -> 0 | AB24: =VLOOKUP(C24,'SAP on Google Cloud'!$1:$1048576,10,FALSE) -> 0 | AC24: =VLOOKUP(C24,'Google Cloud VMware Engine'!$1:$1048576,10,FALSE) -> 0 | AD24: =VLOOKUP(C24,'Google Distributed Cloud'!$1:$1048576,10,FALSE) -> 0 | AE24: =VLOOKUP(C24,'Cloud Security'!$1:$1048576,10,FALSE) -> 0 | AF24: =VLOOKUP(C24,'Security Command Center'!$1:$1048576,10,FALSE) -> 0 | AG24: =VLOOKUP(C24,'Security Operations'!$1:$1048576,10,FALSE) -> 0 | AH24: =VLOOKUP(C24,'Google Threat Intelligence'!$1:$1048576,10,FALSE) -> 0 | AI24: =VLOOKUP(C24,'Vertex AI Platform'!$1:$1048576,10,FALSE) -> 0 | AJ24: =VLOOKUP(C24,'AI Applications'!$1:$1048576,10,FALSE) -> 0 | AK24: =VLOOKUP(C24,'Gemini Enterprise'!$1:$1048576,10,FALSE) -> 0 | AL24: =VLOOKUP(C24,'Customer Engagement Suite'!$1:$1048576,10,FALSE) -> 0 | AM24: =SUM(N24:AL24) -> 0
A25: CHI-11639 | B25: CHI | C25: Daniel Gatica | D25: Principal Consultant | E25: L6 | F25: Venkatesh Kannan | G25: CIDA-01 | H25: CIDA-01-1 | I25: Ops | J25: Data Engineer | K25: DE | L25: Venkatesh Coimbatore Kannan | N25: =VLOOKUP(C25,BigQuery!$1:$1048576,10,FALSE) -> 0 | O25: =VLOOKUP(C25,Looker!$1:$1048576,10,FALSE) -> 0 | P25: =VLOOKUP(C25,Dataflow!$1:$1048576,10,FALSE) -> 0 | Q25: =VLOOKUP(C25,Dataproc!$1:$1048576,10,FALSE) -> 0 | R25: =VLOOKUP(C25,'Google Kubernetes Engine'!$1:$1048576,10,FALSE) -> 0 | S25: =VLOOKUP(C25,'Apigee API Management'!$1:$1048576,10,FALSE) -> 0 | T25: =VLOOKUP(C25,'Cloud Run'!$1:$1048576,10,FALSE) -> 0 | U25: =VLOOKUP(C25,Workspace!$1:$1048576,10,FALSE) -> 0 | V25: =VLOOKUP(C25,'Cloud SQL'!$1:$1048576,10,FALSE) -> 0 | W25: =VLOOKUP(C25,'AlloyDB for PostgreSQL'!$1:$1048576,10,FALSE) -> 0 | X25: =VLOOKUP(C25,Spanner!$1:$1048576,10,FALSE) -> 0 | Y25: =VLOOKUP(C25,Oracle!$1:$1048576,10,FALSE) -> 0 | Z25: =VLOOKUP(C25,'Google Compute Engine'!$1:$1048576,10,FALSE) -> 0 | AA25: =VLOOKUP(C25,'Google Cloud Networking'!$1:$1048576,10,FALSE) -> 0 | AB25: =VLOOKUP(C25,'SAP on Google Cloud'!$1:$1048576,10,FALSE) -> 0 | AC25: =VLOOKUP(C25,'Google Cloud VMware Engine'!$1:$1048576,10,FALSE) -> 0 | AD25: =VLOOKUP(C25,'Google Distributed Cloud'!$1:$1048576,10,FALSE) -> 0 | AE25: =VLOOKUP(C25,'Cloud Security'!$1:$1048576,10,FALSE) -> 0 | AF25: =VLOOKUP(C25,'Security Command Center'!$1:$1048576,10,FALSE) -> 0 | AG25: =VLOOKUP(C25,'Security Operations'!$1:$1048576,10,FALSE) -> 0 | AH25: =VLOOKUP(C25,'Google Threat Intelligence'!$1:$1048576,10,FALSE) -> 0 | AI25: =VLOOKUP(C25,'Vertex AI Platform'!$1:$1048576,10,FALSE) -> 0 | AJ25: =VLOOKUP(C25,'AI Applications'!$1:$1048576,10,FALSE) -> 0 | AK25: =VLOOKUP(C25,'Gemini Enterprise'!$1:$1048576,10,FALSE) -> 0 | AL25: =VLOOKUP(C25,'Customer Engagement Suite'!$1:$1048576,10,FALSE) -> 0 | AM25: =SUM(N25:AL25) -> 0
A26: CHI-16523 | B26: CHI | C26: Daniela Poblete | D26: Consultant | E26: L4 | F26: Jorge Ponce | G26: CIDA-01 | H26: CIDA-01-6 | I26: Ops | J26: Project Manager | K26: SD | L26: Walter Paredes | N26: =VLOOKUP(C26,BigQuery!$1:$1048576,10,FALSE) -> 0 | O26: =VLOOKUP(C26,Looker!$1:$1048576,10,FALSE) -> 0 | P26: =VLOOKUP(C26,Dataflow!$1:$1048576,10,FALSE) -> 0 | Q26: =VLOOKUP(C26,Dataproc!$1:$1048576,10,FALSE) -> 0 | R26: =VLOOKUP(C26,'Google Kubernetes Engine'!$1:$1048576,10,FALSE) -> 0 | S26: =VLOOKUP(C26,'Apigee API Management'!$1:$1048576,10,FALSE) -> 0 | T26: =VLOOKUP(C26,'Cloud Run'!$1:$1048576,10,FALSE) -> 0 | U26: =VLOOKUP(C26,Workspace!$1:$1048576,10,FALSE) -> 0 | V26: =VLOOKUP(C26,'Cloud SQL'!$1:$1048576,10,FALSE) -> 0 | W26: =VLOOKUP(C26,'AlloyDB for PostgreSQL'!$1:$1048576,10,FALSE) -> 0 | X26: =VLOOKUP(C26,Spanner!$1:$1048576,10,FALSE) -> 0 | Y26: =VLOOKUP(C26,Oracle!$1:$1048576,10,FALSE) -> 0 | Z26: =VLOOKUP(C26,'Google Compute Engine'!$1:$1048576,10,FALSE) -> 0 | AA26: =VLOOKUP(C26,'Google Cloud Networking'!$1:$1048576,10,FALSE) -> 0 | AB26: =VLOOKUP(C26,'SAP on Google Cloud'!$1:$1048576,10,FALSE) -> 0 | AC26: =VLOOKUP(C26,'Google Cloud VMware Engine'!$1:$1048576,10,FALSE) -> 0 | AD26: =VLOOKUP(C26,'Google Distributed Cloud'!$1:$1048576,10,FALSE) -> 0 | AE26: =VLOOKUP(C26,'Cloud Security'!$1:$1048576,10,FALSE) -> 0 | AF26: =VLOOKUP(C26,'Security Command Center'!$1:$1048576,10,FALSE) -> 0 | AG26: =VLOOKUP(C26,'Security Operations'!$1:$1048576,10,FALSE) -> 0 | AH26: =VLOOKUP(C26,'Google Threat Intelligence'!$1:$1048576,10,FALSE) -> 0 | AI26: =VLOOKUP(C26,'Vertex AI Platform'!$1:$1048576,10,FALSE) -> 0 | AJ26: =VLOOKUP(C26,'AI Applications'!$1:$1048576,10,FALSE) -> 0 | AK26: =VLOOKUP(C26,'Gemini Enterprise'!$1:$1048576,10,FALSE) -> 0 | AL26: =VLOOKUP(C26,'Customer Engagement Suite'!$1:$1048576,10,FALSE) -> 0 | AM26: =SUM(N26:AL26) -> 0
A27: CHI-13106 | B27: CHI | C27: Daniela Soto | D27: Senior Consultant | E27: L5 | F27: Julio Verdugo | G27: CIDA-01 | H27: CIDA-01-4 | I27: Ops | J27: BI Developer | K27: BI | L27: Walter Paredes | N27: =VLOOKUP(C27,BigQuery!$1:$1048576,10,FALSE) -> 0 | O27: =VLOOKUP(C27,Looker!$1:$1048576,10,FALSE) -> 0 | P27: =VLOOKUP(C27,Dataflow!$1:$1048576,10,FALSE) -> 0 | Q27: =VLOOKUP(C27,Dataproc!$1:$1048576,10,FALSE) -> 0 | R27: =VLOOKUP(C27,'Google Kubernetes Engine'!$1:$1048576,10,FALSE) -> 0 | S27: =VLOOKUP(C27,'Apigee API Management'!$1:$1048576,10,FALSE) -> 0 | T27: =VLOOKUP(C27,'Cloud Run'!$1:$1048576,10,FALSE) -> 0 | U27: =VLOOKUP(C27,Workspace!$1:$1048576,10,FALSE) -> 0 | V27: =VLOOKUP(C27,'Cloud SQL'!$1:$1048576,10,FALSE) -> 0 | W27: =VLOOKUP(C27,'AlloyDB for PostgreSQL'!$1:$1048576,10,FALSE) -> 0 | X27: =VLOOKUP(C27,Spanner!$1:$1048576,10,FALSE) -> 0 | Y27: =VLOOKUP(C27,Oracle!$1:$1048576,10,FALSE) -> 0 | Z27: =VLOOKUP(C27,'Google Compute Engine'!$1:$1048576,10,FALSE) -> 0 | AA27: =VLOOKUP(C27,'Google Cloud Networking'!$1:$1048576,10,FALSE) -> 0 | AB27: =VLOOKUP(C27,'SAP on Google Cloud'!$1:$1048576,10,FALSE) -> 0 | AC27: =VLOOKUP(C27,'Google Cloud VMware Engine'!$1:$1048576,10,FALSE) -> 0 | AD27: =VLOOKUP(C27,'Google Distributed Cloud'!$1:$1048576,10,FALSE) -> 0 | AE27: =VLOOKUP(C27,'Cloud Security'!$1:$1048576,10,FALSE) -> 0 | AF27: =VLOOKUP(C27,'Security Command Center'!$1:$1048576,10,FALSE) -> 0 | AG27: =VLOOKUP(C27,'Security Operations'!$1:$1048576,10,FALSE) -> 0 | AH27: =VLOOKUP(C27,'Google Threat Intelligence'!$1:$1048576,10,FALSE) -> 0 | AI27: =VLOOKUP(C27,'Vertex AI Platform'!$1:$1048576,10,FALSE) -> 0 | AJ27: =VLOOKUP(C27,'AI Applications'!$1:$1048576,10,FALSE) -> 0 | AK27: =VLOOKUP(C27,'Gemini Enterprise'!$1:$1048576,10,FALSE) -> 0 | AL27: =VLOOKUP(C27,'Customer Engagement Suite'!$1:$1048576,10,FALSE) -> 0 | AM27: =SUM(N27:AL27) -> 0
A28: CHI-18680 | B28: CHI | C28: David Hernandez | D28: Senior Consultant | E28: L5 | F28: Walter Paredes | G28: CIDA-01 | H28: CIDA-01-6 | I28: Ops | J28: UI/UX Designer | K28: SD | L28: Walter Paredes | M28: None | N28: =VLOOKUP(C28,BigQuery!$1:$1048576,10,FALSE) -> 0 | O28: =VLOOKUP(C28,Looker!$1:$1048576,10,FALSE) -> 0 | P28: =VLOOKUP(C28,Dataflow!$1:$1048576,10,FALSE) -> 0 | Q28: =VLOOKUP(C28,Dataproc!$1:$1048576,10,FALSE) -> 0 | R28: =VLOOKUP(C28,'Google Kubernetes Engine'!$1:$1048576,10,FALSE) -> 0 | S28: =VLOOKUP(C28,'Apigee API Management'!$1:$1048576,10,FALSE) -> 0 | T28: =VLOOKUP(C28,'Cloud Run'!$1:$1048576,10,FALSE) -> 0 | U28: =VLOOKUP(C28,Workspace!$1:$1048576,10,FALSE) -> 0 | V28: =VLOOKUP(C28,'Cloud SQL'!$1:$1048576,10,FALSE) -> 0 | W28: =VLOOKUP(C28,'AlloyDB for PostgreSQL'!$1:$1048576,10,FALSE) -> 0 | X28: =VLOOKUP(C28,Spanner!$1:$1048576,10,FALSE) -> 0 | Y28: =VLOOKUP(C28,Oracle!$1:$1048576,10,FALSE) -> 0 | Z28: =VLOOKUP(C28,'Google Compute Engine'!$1:$1048576,10,FALSE) -> 0 | AA28: =VLOOKUP(C28,'Google Cloud Networking'!$1:$1048576,10,FALSE) -> 0 | AB28: =VLOOKUP(C28,'SAP on Google Cloud'!$1:$1048576,10,FALSE) -> 0 | AC28: =VLOOKUP(C28,'Google Cloud VMware Engine'!$1:$1048576,10,FALSE) -> 0 | AD28: =VLOOKUP(C28,'Google Distributed Cloud'!$1:$1048576,10,FALSE) -> 0 | AE28: =VLOOKUP(C28,'Cloud Security'!$1:$1048576,10,FALSE) -> 0 | AF28: =VLOOKUP(C28,'Security Command Center'!$1:$1048576,10,FALSE) -> 0 | AG28: =VLOOKUP(C28,'Security Operations'!$1:$1048576,10,FALSE) -> 0 | AH28: =VLOOKUP(C28,'Google Threat Intelligence'!$1:$1048576,10,FALSE) -> 0 | AI28: =VLOOKUP(C28,'Vertex AI Platform'!$1:$1048576,10,FALSE) -> 0 | AJ28: =VLOOKUP(C28,'AI Applications'!$1:$1048576,10,FALSE) -> 0 | AK28: =VLOOKUP(C28,'Gemini Enterprise'!$1:$1048576,10,FALSE) -> 0 | AL28: =VLOOKUP(C28,'Customer Engagement Suite'!$1:$1048576,10,FALSE) -> 0 | AM28: =SUM(N28:AL28) -> 0
A29: CHI-10765 | B29: CHI | C29: Diego Cordova | D29: Principal Consultant | E29: L6 | F29: Venkatesh Kannan | G29: CIDA-01 | H29: CIDA-01-1 | I29: Ops | J29: BI Developer | K29: DE | L29: Venkatesh Coimbatore Kannan | N29: =VLOOKUP(C29,BigQuery!$1:$1048576,10,FALSE) -> 0 | O29: =VLOOKUP(C29,Looker!$1:$1048576,10,FALSE) -> 0 | P29: =VLOOKUP(C29,Dataflow!$1:$1048576,10,FALSE) -> 0 | Q29: =VLOOKUP(C29,Dataproc!$1:$1048576,10,FALSE) -> 0 | R29: =VLOOKUP(C29,'Google Kubernetes Engine'!$1:$1048576,10,FALSE) -> 0 | S29: =VLOOKUP(C29,'Apigee API Management'!$1:$1048576,10,FALSE) -> 0 | T29: =VLOOKUP(C29,'Cloud Run'!$1:$1048576,10,FALSE) -> 0 | U29: =VLOOKUP(C29,Workspace!$1:$1048576,10,FALSE) -> 0 | V29: =VLOOKUP(C29,'Cloud SQL'!$1:$1048576,10,FALSE) -> 0 | W29: =VLOOKUP(C29,'AlloyDB for PostgreSQL'!$1:$1048576,10,FALSE) -> 0 | X29: =VLOOKUP(C29,Spanner!$1:$1048576,10,FALSE) -> 0 | Y29: =VLOOKUP(C29,Oracle!$1:$1048576,10,FALSE) -> 0 | Z29: =VLOOKUP(C29,'Google Compute Engine'!$1:$1048576,10,FALSE) -> 0 | AA29: =VLOOKUP(C29,'Google Cloud Networking'!$1:$1048576,10,FALSE) -> 0 | AB29: =VLOOKUP(C29,'SAP on Google Cloud'!$1:$1048576,10,FALSE) -> 0 | AC29: =VLOOKUP(C29,'Google Cloud VMware Engine'!$1:$1048576,10,FALSE) -> 0 | AD29: =VLOOKUP(C29,'Google Distributed Cloud'!$1:$1048576,10,FALSE) -> 0 | AE29: =VLOOKUP(C29,'Cloud Security'!$1:$1048576,10,FALSE) -> 0 | AF29: =VLOOKUP(C29,'Security Command Center'!$1:$1048576,10,FALSE) -> 0 | AG29: =VLOOKUP(C29,'Security Operations'!$1:$1048576,10,FALSE) -> 0 | AH29: =VLOOKUP(C29,'Google Threat Intelligence'!$1:$1048576,10,FALSE) -> 0 | AI29: =VLOOKUP(C29,'Vertex AI Platform'!$1:$1048576,10,FALSE) -> 0 | AJ29: =VLOOKUP(C29,'AI Applications'!$1:$1048576,10,FALSE) -> 0 | AK29: =VLOOKUP(C29,'Gemini Enterprise'!$1:$1048576,10,FALSE) -> 0 | AL29: =VLOOKUP(C29,'Customer Engagement Suite'!$1:$1048576,10,FALSE) -> 0 | AM29: =SUM(N29:AL29) -> 0
A30: CHI-15485 | B30: CHI | C30: Diego Hevia | D30: Senior Analyst | E30: L3 | F30: Julio Verdugo | G30: CIDA-01 | H30: CIDA-01-4 | I30: Ops | J30: BI Developer | K30: BI | L30: Walter Paredes | N30: =VLOOKUP(C30,BigQuery!$1:$1048576,10,FALSE) -> 0 | O30: =VLOOKUP(C30,Looker!$1:$1048576,10,FALSE) -> 0 | P30: =VLOOKUP(C30,Dataflow!$1:$1048576,10,FALSE) -> 0 | Q30: =VLOOKUP(C30,Dataproc!$1:$1048576,10,FALSE) -> 0 | R30: =VLOOKUP(C30,'Google Kubernetes Engine'!$1:$1048576,10,FALSE) -> 0 | S30: =VLOOKUP(C30,'Apigee API Management'!$1:$1048576,10,FALSE) -> 0 | T30: =VLOOKUP(C30,'Cloud Run'!$1:$1048576,10,FALSE) -> 0 | U30: =VLOOKUP(C30,Workspace!$1:$1048576,10,FALSE) -> 0 | V30: =VLOOKUP(C30,'Cloud SQL'!$1:$1048576,10,FALSE) -> 0 | W30: =VLOOKUP(C30,'AlloyDB for PostgreSQL'!$1:$1048576,10,FALSE) -> 0 | X30: =VLOOKUP(C30,Spanner!$1:$1048576,10,FALSE) -> 0 | Y30: =VLOOKUP(C30,Oracle!$1:$1048576,10,FALSE) -> 0 | Z30: =VLOOKUP(C30,'Google Compute Engine'!$1:$1048576,10,FALSE) -> 0 | AA30: =VLOOKUP(C30,'Google Cloud Networking'!$1:$1048576,10,FALSE) -> 0 | AB30: =VLOOKUP(C30,'SAP on Google Cloud'!$1:$1048576,10,FALSE) -> 0 | AC30: =VLOOKUP(C30,'Google Cloud VMware Engine'!$1:$1048576,10,FALSE) -> 0 | AD30: =VLOOKUP(C30,'Google Distributed Cloud'!$1:$1048576,10,FALSE) -> 0 | AE30: =VLOOKUP(C30,'Cloud Security'!$1:$1048576,10,FALSE) -> 0 | AF30: =VLOOKUP(C30,'Security Command Center'!$1:$1048576,10,FALSE) -> 0 | AG30: =VLOOKUP(C30,'Security Operations'!$1:$1048576,10,FALSE) -> 0 | AH30: =VLOOKUP(C30,'Google Threat Intelligence'!$1:$1048576,10,FALSE) -> 0 | AI30: =VLOOKUP(C30,'Vertex AI Platform'!$1:$1048576,10,FALSE) -> 0 | AJ30: =VLOOKUP(C30,'AI Applications'!$1:$1048576,10,FALSE) -> 0 | AK30: =VLOOKUP(C30,'Gemini Enterprise'!$1:$1048576,10,FALSE) -> 0 | AL30: =VLOOKUP(C30,'Customer Engagement Suite'!$1:$1048576,10,FALSE) -> 0 | AM30: =SUM(N30:AL30) -> 0
A31: INC-18223 | B31: INC | C31: Mihidum Gunasekara | D31: Principal Consultant | E31: L6 | F31: Arnav Sharma | G31: CIDA-05 | H31: CIDA-05-2 | I31: Ops | J31: Data Scientist | K31: DS | L31: Arnav Sharma | N31: =VLOOKUP(C31,BigQuery!$1:$1048576,10,FALSE) -> 0 | O31: =VLOOKUP(C31,Looker!$1:$1048576,10,FALSE) -> 0 | P31: =VLOOKUP(C31,Dataflow!$1:$1048576,10,FALSE) -> 0 | Q31: =VLOOKUP(C31,Dataproc!$1:$1048576,10,FALSE) -> 0 | R31: =VLOOKUP(C31,'Google Kubernetes Engine'!$1:$1048576,10,FALSE) -> 0 | S31: =VLOOKUP(C31,'Apigee API Management'!$1:$1048576,10,FALSE) -> 0 | T31: =VLOOKUP(C31,'Cloud Run'!$1:$1048576,10,FALSE) -> 0 | U31: =VLOOKUP(C31,Workspace!$1:$1048576,10,FALSE) -> 0 | V31: =VLOOKUP(C31,'Cloud SQL'!$1:$1048576,10,FALSE) -> 0 | W31: =VLOOKUP(C31,'AlloyDB for PostgreSQL'!$1:$1048576,10,FALSE) -> 0 | X31: =VLOOKUP(C31,Spanner!$1:$1048576,10,FALSE) -> 0 | Y31: =VLOOKUP(C31,Oracle!$1:$1048576,10,FALSE) -> 0 | Z31: =VLOOKUP(C31,'Google Compute Engine'!$1:$1048576,10,FALSE) -> 0 | AA31: =VLOOKUP(C31,'Google Cloud Networking'!$1:$1048576,10,FALSE) -> 0 | AB31: =VLOOKUP(C31,'SAP on Google Cloud'!$1:$1048576,10,FALSE) -> 0 | AC31: =VLOOKUP(C31,'Google Cloud VMware Engine'!$1:$1048576,10,FALSE) -> 0 | AD31: =VLOOKUP(C31,'Google Distributed Cloud'!$1:$1048576,10,FALSE) -> 0 | AE31: =VLOOKUP(C31,'Cloud Security'!$1:$1048576,10,FALSE) -> 0 | AF31: =VLOOKUP(C31,'Security Command Center'!$1:$1048576,10,FALSE) -> 0 | AG31: =VLOOKUP(C31,'Security Operations'!$1:$1048576,10,FALSE) -> 0 | AH31: =VLOOKUP(C31,'Google Threat Intelligence'!$1:$1048576,10,FALSE) -> 0 | AI31: =VLOOKUP(C31,'Vertex AI Platform'!$1:$1048576,10,FALSE) -> 0 | AJ31: =VLOOKUP(C31,'AI Applications'!$1:$1048576,10,FALSE) -> 0 | AK31: =VLOOKUP(C31,'Gemini Enterprise'!$1:$1048576,10,FALSE) -> 0 | AL31: =VLOOKUP(C31,'Customer Engagement Suite'!$1:$1048576,10,FALSE) -> 0 | AM31: =SUM(N31:AL31) -> 0
